<?xml version="1.0"?>
<robot xmlns:xacro="http://www.ros.org/wiki/xacro" name="robot_xacro">
    <xacro:include filename="$(find exp_assignment3)/urdf/robot.gazebo" />

    <xacro:property name="length_wheel" value="0.04" />
    <xacro:property name="radius_wheel" value="0.1" />

    <xacro:macro name="default_inertial" params="mass">
        <inertial>
            <mass value="${mass}" />
            <origin rpy="0 1.5707 1.5707" xyz="0 0 0" />
            <inertia ixx="0.000526666666667" ixy="0" ixz="0" iyy="0.000526666666667" iyz="0" izz="0.001" />
        </inertial>
    </xacro:macro>

    <xacro:macro name="wheel_geometry">
        <geometry>
            <cylinder length="${length_wheel}" radius="${radius_wheel}" />
        </geometry>
    </xacro:macro>

    <link name="link_chassis">
        <!-- pose and inertial -->
        <pose>0 0 0.1 0 0 0</pose>
        <inertial>
            <mass value="20" />
            <origin rpy="0 0 0" xyz="0 0 0.1" />
            <inertia ixx="0.0395416666667" ixy="0" ixz="0" iyy="0.106208333333" iyz="0" izz="0.106208333333" />
        </inertial>
        <!-- body -->
        <collision name="collision_chassis">
            <geometry>
                <box size="0.5 0.3 0.07" />
            </geometry>
        </collision>
        <visual>
            <origin rpy="0 0 0" xyz="0 0 0" />
            <geometry>
                <box size="0.5 0.3 0.07" />
            </geometry>
            <material name="blue" />
        </visual>
    </link>

    <link name="link_castor_mount">
        <collision>
            <origin rpy="0 0 0" xyz="0 0 0" />
            <geometry>
                <box size="0.057 0.10 0.0057"/>
            </geometry>
        </collision>
        <visual>
            <origin xyz="0 0 0" rpy="0 0 0"/>
            <geometry>
                <box size="0.057 0.05 0.0057"/>
            </geometry>
            <material name="grey">
                <color rgba="1 0 0 1"/>
            </material>
        </visual>
        <inertial>
            <origin rpy="0 0 0" xyz="0 0 0" />
            <mass value="0.25"/>
            <inertia
                ixx="${0.25*(0.05*0.05+0.0057*0.0057)/12}"
                ixy="0"
                ixz="0"
                iyy="${0.25*(0.057*0.057+0.0057*0.0057)/12}"
                iyz="0"
                izz="${0.25*(0.057*0.057+0.0057*0.0057)/12}"/>
        </inertial>
    </link>

    <joint name="joint_castor_mount" type="fixed">
        <!-- <origin xyz="0.15 0.075 -0.035" rpy="0 0 0"/> -->
        <origin xyz="0.15 0 -0.035" rpy="0 0 0"/>
        <parent link="link_chassis"/>
        <child link="link_castor_mount"/>
    </joint>

    <link name="link_castor_dummy">
        <collision>
            <origin rpy="0 0 0" xyz="0 0 0" />
            <geometry>
                <box size="0.01 0.01 0.01"/>
            </geometry>
        </collision>
        <visual>
            <origin xyz="0 0 0" rpy="0 0 0"/>
            <geometry>
                <box size="0.01 0.01 0.01"/>
            </geometry>
            <material name="grey">
                <color rgba="1 0 0 1"/>
            </material>
        </visual>
        <inertial>
            <origin rpy="0 0 0" xyz="0 0 0" />
            <mass value="0.25"/>
            <inertia
                ixx="${0.25*(0.01*0.01+0.01*0.01)/12}"
                ixy="0"
                ixz="0"
                iyy="${0.25*(0.01*0.01+0.01*0.01)/12}"
                iyz="0"
                izz="${0.25*(0.01*0.01+0.01*0.01)/12}"/>
        </inertial>
    </link>

    <joint name="joint_castor_dummy" type="continuous">
        <origin rpy="0 0 0" xyz="0 0 -0.01" />
        <child link="link_castor_dummy" />
        <parent link="link_castor_mount" />
        <axis rpy="0 0 0" xyz="0 0 1" />
        <!-- <limit effort="1000.0" lower="-1" upper="1" velocity="0.5" /> -->
        <limit effort="10000" velocity="1000" />
        <joint_properties damping="1.0" friction="1.0" />
    </joint>

    <transmission name="castor_dummy_transm">
        <type>transmission_interface/SimpleTransmission</type>
        <joint name="joint_castor_dummy">
            <hardwareInterface>hardware_interface/EffortJointInterface</hardwareInterface>
        </joint>
        <actuator name="motor2">
            <hardwareInterface>hardware_interface/EffortJointInterface</hardwareInterface>
            <mechanicalInterface>1</mechanicalInterface>
        </actuator>
    </transmission>

    <link name="link_castor_wheel">
        <collision>
            <origin rpy="0 1.5707 1.5707" xyz="0 0 0" />
            <geometry>
                <cylinder length="0.04" radius="0.024"/>
            </geometry>
        </collision>
        <visual>
            <origin rpy="0 1.5707 1.5707" xyz="0 0 0" />
            <geometry>
                <cylinder length="0.04" radius="0.024"/>
            </geometry>
            <material name="red"/>
        </visual>
        <xacro:default_inertial mass="0.1" />
    </link>

    <joint name="joint_castor_wheel" type="continuous">
        <axis rpy="0 0 0" xyz="0 1 0"/>
        <parent link="link_castor_dummy"/>
        <child link="link_castor_wheel"/>
        <origin rpy="0 0 0" xyz="-0.03 0 -0.035" />
        <joint_properties damping="1.0" friction="1.0" />
    </joint>

    <!-- transmission -->

    <transmission name="castor_wheel_transm">
        <type>transmission_interface/SimpleTransmission</type>
        <joint name="joint_castor_wheel">
            <hardwareInterface>hardware_interface/EffortJointInterface</hardwareInterface>
        </joint>
        <actuator name="motor1">
            <hardwareInterface>hardware_interface/EffortJointInterface</hardwareInterface>
            <mechanicalInterface>1</mechanicalInterface>
        </actuator>
    </transmission>

    <link name="link_right_wheel">
        <xacro:default_inertial mass="0.2" />
        <collision name="link_right_wheel_collision">
            <origin rpy="0 1.5707 1.5707" xyz="0 0 0" />
            <xacro:wheel_geometry />
        </collision>
        <visual name="link_right_wheel_visual">
            <origin rpy="0 1.5707 1.5707" xyz="0 0 0" />
            <xacro:wheel_geometry />
            <material name="red" />
        </visual>
    </link>

    <link name="link_left_wheel">
        <xacro:default_inertial mass="0.2" />
        <collision name="link_left_wheel_collision">
            <origin rpy="0 1.5707 1.5707" xyz="0 0 0" />
            <xacro:wheel_geometry />
        </collision>
        <visual name="link_left_wheel_visual">
            <origin rpy="0 1.5707 1.5707" xyz="0 0 0" />
            <xacro:wheel_geometry />
            <material name="red" />
        </visual>
    </link>

    <joint name="joint_right_wheel" type="continuous">
        <origin rpy="0 0 0" xyz="-0.05 0.15 0" />
        <child link="link_right_wheel" />
        <parent link="link_chassis" />
        <axis rpy="0 0 0" xyz="0 1 0" />
        <joint_properties damping="1.0" friction="1.0" />
    </joint>


    <joint name="joint_left_wheel" type="continuous">
        <origin rpy="0 0 0" xyz="-0.05 -0.15 0" />
        <child link="link_left_wheel" />
        <parent link="link_chassis" />
        <axis rpy="0 0 0" xyz="0 1 0" />
        <joint_properties damping="1.0" friction="1.0" />
    </joint>

    <link name="camera_link">
        <collision>
            <origin xyz="0 0 0.025" rpy="0 0 0"/>
            <geometry>
                <box size="0.05 0.05 0.05"/>
            </geometry>
        </collision>
        <visual>
            <origin xyz="0 0 0.025" rpy="0 0 0"/>
            <geometry>
                <box size="0.05 0.05 0.05"/>
            </geometry>
            <material name="orange">
                <color rgba="1 0 0 1"/>
            </material>
        </visual>
        <!-- <inertial>
      <mass value="1e-5" />
      <origin xyz="0 0 0" rpy="0 0 0"/>
      <inertia ixx="1e-6" ixy="0" ixz="0" iyy="1e-6" iyz="0" izz="1e-6" />
    </inertial> -->
    </link>

    <joint name="camera_joint" type="fixed">
        <axis xyz="0 1 0" />
        <origin xyz="0.2 0 0.035" rpy="0 0 0"/>
        <parent link="link_chassis"/>
        <child link="camera_link"/>
    </joint>

    <!-- <link name="cameradepth_link">
        <collision>
            <origin xyz="0 0 0.025" rpy="0 0 0"/>
            <geometry>
                <box size="0.05 0.05 0.05"/>
            </geometry>
        </collision>
        <visual>
            <origin xyz="0 0 0.025" rpy="0 0 0"/>
            <geometry>
                <box size="0.05 0.05 0.05"/>
            </geometry>
            <material name="orange"/>
        </visual>
        <inertial>
      <origin xyz="0 0 0" rpy="0 0 0"/>
      <mass value="0.1"/>
      <inertia ixx="1e-6" ixy="0" ixz="0" iyy="1e-6" iyz="0" izz="1e-6" />
    </inertial>
    </link>

    <joint name="camera_depth_joint" type="fixed">
        <origin xyz="0.2 -0.05 0.035" rpy="0 0 0 "/>
        <parent link="link_chassis"/>
        <child link="cameradepth_link"/>
    </joint> -->

    <link name="hokuyo_link">
        <collision>
            <origin xyz="0 0 0.00125" rpy="0 0 0"/>
            <geometry>
                <box size="0.025 0.025 0.025"/>
            </geometry>
        </collision>
        <visual>
            <origin xyz="0 0 0.0125" rpy="0 0 0"/>
            <geometry>
                <box size="0.025 0.025 0.025"/>
            </geometry>
            <material name="red"/>
        </visual>
        <!-- <inertial>
      <mass value="1e-5" />
      <origin xyz="0 0 0" rpy="0 0 0"/>
      <inertia ixx="1e-6" ixy="0" ixz="0" iyy="1e-6" iyz="0" izz="1e-6" />
    </inertial> -->
    </link>

    <joint name="hokuyo_joint" type="fixed">
        <axis xyz="0 1 0" />
        <origin xyz="0 0 0.05" rpy="0 0 0"/>
        <parent link="camera_link"/>
        <child link="hokuyo_link"/>
    </joint>

</robot>
